Workbook

Sheet Cover
A1: Cover
A2: Metadata for Capital Outturn Return (COR) time series: 2018-19 to 2023-24
A3: Last updated: 4 July 2025
A4: Contact: capitaldata@communities.gov.uk
A5: Description
A6: The information in this workbook explains the data items used when publishing the time series containing Capital Outturn Return (COR) entries for the time period 2018-19 to 2023-24. These can be found at the link in the cell below.
A7: Local authority capital expenditure and receipts in England final outturn time series (www.gov.uk)
A8: COR data are used to compile yearly Accredited Official Statistics release Local Authority Capital Expenditure & Receipts England Final Outturn which is published in autumn every year. These can be found at the link in the cell below. | D8: .
A9: Statistical collection: Local authority capital expenditure, receipts and financing
A10: These statistics are Accredited Official Statistics. This status means that these statistics comply with the highest standards of trustworthiness, quality and public value as set out in the Code of Practice for Statistics and should be labelled ‘accredited official statistics’. Accredited official statistics are called National Statistics in the Statistics and Registration Service Act 2007. These accredited official statistics were independently reviewed by the Office for Statistics Regulation in April 2012. They comply with the standards of trustworthiness, quality and value in the Code of Practice for Statistics and should be labelled ‘accredited official statistics’. Our statistical practice is regulated by the Office for Statistics Regulation (OSR). OSR sets the standards of trustworthiness, quality and value in the Code of Practice for Statistics to which all producers of official statistics should adhere. You are welcome to contact us directly by emailing capitaldata@levellingup.gov.uk with any comments about how we meet these standards. Alternatively, you can contact OSR by emailing regulation@statistics.gov.uk or via the OSR website. Further information on accredited official statistics can also be found on the OSR website using the link in the cell below:
A11: Accredited official statistics
A12: The workbook has been compiled by the Local Government Finance - Analysis and Data division of Ministry of Housing, Communities and Local Government
A13: We welcome comments and suggestions for further improvement or about your experiences with this product. This may include comments on data quality, timing and the format of the statistics. Please contact us at:
A14: capitaldata@communities.gov.uk

Sheet Contents
A1: Table of Contents
A2: This worksheet contains 1 table.
A3: Sheet Name | B3: Sheet Title
A4: Cover | B4: Background information about how this information should be used
A5: Notes | B5: Notes used in this workbook
A6: Release log | B6: A release log of the multi-year time series
A7: Data dictionary | B7: Metadata description of variables included in the data set
A8: Data notes | B8: Metadata on data points included in the data set. Includes information about known issues with data and any caveats
A9: Local authorities | B9: Metadata on local authorities that have been included in the data set. Includes information about local authority reorganisations
A10: Totals | B10: Metadata on aggregated local authority totals

Sheet Notes
A1: Notes
A2: This worksheet contains 1 table.
A3: Note Number | B3: Note Text
A4: [note 1] | B4: The start and end date represent the first and last year in the time series where data exists for the relevant variable or local authority. The date is coded in a YYYYMM format, therefore 201903 represents March 2019. The last month of the financial year is used to refer to data for the whole year, therefore 201903 refers to the 2018-2019 financial year.
A5: [note 2] | B5: Row and column numbers indicate the variable's current location within the standard COR form. Row and column numbers can be used alongside form name to locate a variable within the COR form.
A6: [note 3] | B6: The 'notes' column contains details relating to data items or LAs being added / removed / split / merged, which can serve as caveats to explain differences over time when using the data as part of a time series.
A7: [note 4] | B7: In addition to the widely used 8 digit codes allocated by the ONS, a four digit code is typically created for new authorities in MHCLG allocation systems. Both codes are provided for convenience.
A8: [note 5] | B8: Variables from the GLA COR form.
A9: [note 6] | B9: EandR1C includes variables that appears only on the GLA COR form.

Sheet Release_log
A1: Release log
A2: This worksheet contains one table.
A3: Some cells refer to notes which can be found in the 'Notes' worksheet.
A4: Version Number | B4: Release Date | C4: Year Affected [note 1] | D4: Details
A5: 1 | B5: 45442 | C5: 202303 | D5: First release of 2022-2023 Capital Outturn Return data. Data for 416/425 local authorities included. Last revision date: 30 May 2024. To be updated when remaining authorities submit their returns.
A6: 1 | B6: 45442 | C6: 202203 | D6: Final release of 2021-2022 Capital Outturn Return data. Data for 425/425 local authorities included. Last revision date: 30 May 2024.
A7: 1 | B7: 45442 | C7: 202103 | D7: Final release of 2020-2021 Capital Outturn Return data. Data for 431/431 local authorities included. Last revision date: 30 May 2024.
A8: 1 | B8: 45442 | C8: 202003 | D8: Final release of 2019-2020 Capital Outturn Return data. Data for 435/435 local authorities included. Last revision date: 30 May 2024.
A9: 1 | B9: 45442 | C9: 201903 | D9: Final release of 2018-2019 Capital Outturn Return data. Data for 443/443 local authorities included. Last revision date: 30 May 2024.
A10: 2 | B10: 45624 | C10: 202403 | D10: First release of 2023-2024 Capital Outturn Return data. Data for 408/410 local authorities included. Last revision date: 28 November 2024. To be updated when remaining authorities submit their returns.
A11: 3 | B11: 45842 | C11: 202303 | D11: Final release of 2022-2023 Capital Outturn Return data. Data for 425/425 local authorities included. Last revision date: 17 June 2025.
A12: 3 | B12: 45842 | C12: 202403 | D12: Final release of 2023-2024 Capital Outturn Return data. Data for 410/410 local authorities included. Last revision date: 17 June 2025.

Sheet Data_dictionary
A1: Description of data items used within the time series publication
A2: This worksheet contains one table.
A3: Some cells refer to notes which can be found in the 'Notes' worksheet. Blank cells in the 'End' column (column E) mean the variable is still in current use. Blank cells in the 'Notes' column (column I) mean there are no notes for that variable.
A4: Variable | B4: Data_Type | C4: Description | D4: Start [note 1] | E4: End [note 1] | F4: Form_Name | G4: Row_Number [note 2] | H4: Column_Number [note 2] | I4: Notes [note 3]
A5: PeriodCode | B5: date | C5: The date in YYYYMM format which represents the end of the financial year. For example, 201903 represents March 2019, which was the end of the 2018-2019 fiscal year. The Capital Outturn Return contains expenditure which took place over the course of a whole financial year. | D5: 201903 | F5: all | G5: admin data, not coming from form cells | H5: admin data, not coming from form cells
A6: LA_LGF_Code | B6: string | C6: A Local Government Finance code, which MHCLG uses internally to represent local authorities. These are unique to each local authority, similar to the ONS local authority code. | D6: 201903 | F6: all | G6: admin data, not coming from form cells | H6: admin data, not coming from form cells
A7: ONS_Code | B7: string | C7: The ONS local authority code. | D7: 201903 | F7: all | G7: admin data, not coming from form cells | H7: admin data, not coming from form cells
A8: LA_Name | B8: string | C8: The name of the local authority | D8: 201903 | F8: all | G8: admin data, not coming from form cells | H8: admin data, not coming from form cells
A9: LA_Class | B9: string | C9: The classification of the local authority. A local authority's classification is related to the functions it carries out and how they are financed. | D9: 201903 | F9: all | G9: admin data, not coming from form cells | H9: admin data, not coming from form cells
A10: LA_Subclass | B10: string | C10: The detailed classification of the local authority. A local authority's classification is related to the functions it carries out and how they are financed. | D10: 201903 | F10: all | G10: admin data, not coming from form cells | H10: admin data, not coming from form cells
A11: Status | B11: string | C11: The submission status. Takes one of three values: submitted, not submitted, or total. Totals are calculated, further information available on the Totals tab. | D11: 201903 | F11: all | G11: admin data, not coming from form cells | H11: admin data, not coming from form cells
A12: EandR1-eduerlprm-explndbld | B12: numeric | C12: Early Years & Primary Schools - Acquisition of land & existing buildings | D12: 201903 | F12: =LEFT(Data_dictionary!$A12,FIND("-",Data_dictionary!$A12)-1) -> EandR1 | G12: R01 | H12: C01
A13: EandR1-eduerlprm-expcnscnvrnv | B13: numeric | C13: Early Years & Primary Schools - New construction, conversion & renovation | D13: 201903 | F13: =LEFT(Data_dictionary!$A13,FIND("-",Data_dictionary!$A13)-1) -> EandR1 | G13: R01 | H13: C02
A14: EandR1-eduerlprm-expvhc | B14: numeric | C14: Early Years & Primary Schools - Vehicles | D14: 201903 | F14: =LEFT(Data_dictionary!$A14,FIND("-",Data_dictionary!$A14)-1) -> EandR1 | G14: R01 | H14: C03
A15: EandR1-eduerlprm-expeqpmch | B15: numeric | C15: Early Years & Primary Schools - Plant, furniture & equipment | D15: 201903 | F15: =LEFT(Data_dictionary!$A15,FIND("-",Data_dictionary!$A15)-1) -> EandR1 | G15: R01 | H15: C04
A16: EandR1-eduerlprm-expvhceqpmch | B16: numeric | C16: Early Years & Primary Schools - Vehicles, plant, furniture & equipment | D16: 201903 | F16: =LEFT(Data_dictionary!$A16,FIND("-",Data_dictionary!$A16)-1) -> EandR1 | G16: R01 | H16: C05
A17: EandR1-eduerlprm-expint | B17: numeric | C17: Early Years & Primary Schools - Intangible fixed assets | D17: 201903 | F17: =LEFT(Data_dictionary!$A17,FIND("-",Data_dictionary!$A17)-1) -> EandR1 | G17: R01 | H17: C06
A18: EandR1-eduerlprm-exptotfa | B18: numeric | C18: Early Years & Primary Schools - Total expenditure on fixed assets | D18: 201903 | F18: =LEFT(Data_dictionary!$A18,FIND("-",Data_dictionary!$A18)-1) -> EandR1 | G18: R01 | H18: C07
A19: EandR1-eduscn-explndbld | B19: numeric | C19: Secondary Schools - Acquisition of land & existing buildings | D19: 201903 | F19: =LEFT(Data_dictionary!$A19,FIND("-",Data_dictionary!$A19)-1) -> EandR1 | G19: R02 | H19: C01
A20: EandR1-eduscn-expcnscnvrnv | B20: numeric | C20: Secondary Schools - New construction, conversion & renovation | D20: 201903 | F20: =LEFT(Data_dictionary!$A20,FIND("-",Data_dictionary!$A20)-1) -> EandR1 | G20: R02 | H20: C02
A21: EandR1-eduscn-expvhc | B21: numeric | C21: Secondary Schools - Vehicles | D21: 201903 | F21: =LEFT(Data_dictionary!$A21,FIND("-",Data_dictionary!$A21)-1) -> EandR1 | G21: R02 | H21: C03
A22: EandR1-eduscn-expeqpmch | B22: numeric | C22: Secondary Schools - Plant, furniture & equipment | D22: 201903 | F22: =LEFT(Data_dictionary!$A22,FIND("-",Data_dictionary!$A22)-1) -> EandR1 | G22: R02 | H22: C04
A23: EandR1-eduscn-expvhceqpmch | B23: numeric | C23: Secondary Schools - Vehicles, plant, furniture & equipment | D23: 201903 | F23: =LEFT(Data_dictionary!$A23,FIND("-",Data_dictionary!$A23)-1) -> EandR1 | G23: R02 | H23: C05
... A398: EandR1-eduerlprm-expgrnla | B398: numeric | C398: Early Years & Primary Schools - Grants, of which to other local authorities | D398: 201903 | F398: =LEFT(Data_dictionary!$A398,FIND("-",Data_dictionary!$A398)-1) -> EandR1 | G398: R01 | H398: C09
A399: EandR1-eduerlprm-expgrngla | B399: numeric | C399: Early Years & Primary Schools - Grants, of which within GLA group | D399: 201903 | F399: =LEFT(Data_dictionary!$A399,FIND("-",Data_dictionary!$A399)-1) -> EandR1 | I399: [note 5]
A400: EandR1-eduerlprm-expgrnoth | B400: numeric | C400: Early Years & Primary Schools - Grants, excluding to local authorities | D400: 201903 | F400: =LEFT(Data_dictionary!$A400,FIND("-",Data_dictionary!$A400)-1) -> EandR1 | G400: R01 | H400: C10
A401: EandR1-eduerlprm-explns | B401: numeric | C401: Early Years & Primary Schools - Loans or other financial assistance | D401: 201903 | F401: =LEFT(Data_dictionary!$A401,FIND("-",Data_dictionary!$A401)-1) -> EandR1 | G401: R01 | H401: C11
A402: EandR1-eduerlprm-explnsla | B402: numeric | C402: Early Years & Primary Schools - Loans or other financial assistance, of which to other local authorities | D402: 201903 | F402: =LEFT(Data_dictionary!$A402,FIND("-",Data_dictionary!$A402)-1) -> EandR1 | G402: R01 | H402: C12
A403: EandR1-eduerlprm-explnsgla | B403: numeric | C403: Early Years & Primary Schools - Loans or other financial assistance, of which within GLA group | D403: 201903 | F403: =LEFT(Data_dictionary!$A403,FIND("-",Data_dictionary!$A403)-1) -> EandR1 | I403: [note 5]
A404: EandR1-eduerlprm-explnsoth | B404: numeric | C404: Early Years & Primary Schools - Loans or other financial assistance, excluding to local authorities | D404: 201903 | F404: =LEFT(Data_dictionary!$A404,FIND("-",Data_dictionary!$A404)-1) -> EandR1 | G404: R01 | H404: C13
A405: EandR1-eduerlprm-expshrlns | B405: numeric | C405: Early Years & Primary Schools - Acquisition of share or loan capital | D405: 201903 | F405: =LEFT(Data_dictionary!$A405,FIND("-",Data_dictionary!$A405)-1) -> EandR1 | G405: R01 | H405: C14
A406: EandR1-eduerlprm-expshrlnsgla | B406: numeric | C406: Early Years & Primary Schools - Acquisition of share or loan capital, of which within GLA group | D406: 201903 | F406: =LEFT(Data_dictionary!$A406,FIND("-",Data_dictionary!$A406)-1) -> EandR1 | I406: [note 5]
A407: EandR1-eduerlprm-expshrlnsoth | B407: numeric | C407: Early Years & Primary Schools - Acquisition of share or loan capital, of which other | D407: 201903 | F407: =LEFT(Data_dictionary!$A407,FIND("-",Data_dictionary!$A407)-1) -> EandR1 | I407: [note 5]
A408: EandR1-eduerlprm-exptotfin | B408: numeric | C408: Early Years & Primary Schools - Total financial expenditure | D408: 201903 | F408: =LEFT(Data_dictionary!$A408,FIND("-",Data_dictionary!$A408)-1) -> EandR1 | G408: R01 | H408: C15
A409: EandR1-eduscn-expgrn | B409: numeric | C409: Secondary Schools - Grants | D409: 201903 | F409: =LEFT(Data_dictionary!$A409,FIND("-",Data_dictionary!$A409)-1) -> EandR1 | G409: R02 | H409: C08
A410: EandR1-eduscn-expgrnla | B410: numeric | C410: Secondary Schools - Grants, of which to other local authorities | D410: 201903 | F410: =LEFT(Data_dictionary!$A410,FIND("-",Data_dictionary!$A410)-1) -> EandR1 | G410: R02 | H410: C09
A411: EandR1-eduscn-expgrngla | B411: numeric | C411: Secondary Schools - Grants, of which within GLA group | D411: 201903 | F411: =LEFT(Data_dictionary!$A411,FIND("-",Data_dictionary!$A411)-1) -> EandR1 | I411: [note 5]
A412: EandR1-eduscn-expgrnoth | B412: numeric | C412: Secondary Schools - Grants, excluding to local authorities | D412: 201903 | F412: =LEFT(Data_dictionary!$A412,FIND("-",Data_dictionary!$A412)-1) -> EandR1 | G412: R02 | H412: C10
A413: EandR1-eduscn-explns | B413: numeric | C413: Secondary Schools - Loans or other financial assistance | D413: 201903 | F413: =LEFT(Data_dictionary!$A413,FIND("-",Data_dictionary!$A413)-1) -> EandR1 | G413: R02 | H413: C11
A414: EandR1-eduscn-explnsla | B414: numeric | C414: Secondary Schools - Loans or other financial assistance, of which to other local authorities | D414: 201903 | F414: =LEFT(Data_dictionary!$A414,FIND("-",Data_dictionary!$A414)-1) -> EandR1 | G414: R02 | H414: C12
...

Sheet Data_notes
A1: Data notes
A2: This worksheet contains one table.
A3: Note_Number | B3: Year | C3: Local_Authority_Name | D3: Note
A4: 1 | B4: 201903 | C4: North East Lincolnshire | D4: This local authority submitted HRA figures but does not have an HRA. The published suplementary COR table included individual LA data only for LAs with an HRA. The totals also exclude these figures, summing only figures from LAs with an HRA. The time series data shows the figures reported by the individual LA, despite not having an HRA, and includes them when calculating totals.
A5: 2 | B5: 201903 | C5: Peterborough | D5: This local authority submitted HRA figures but does not have an HRA. The published suplementary COR table included individual LA data only for LAs with an HRA. The totals also exclude these figures, summing only figures from LAs with an HRA. The time series data shows the figures reported by the individual LA, despite not having an HRA, and includes them when calculating totals.
A6: 3 | B6: 202003 | C6: Dorset (UA) | D6: This local authority submitted HRA figures but does not have an HRA. The published suplementary COR table included individual LA data only for LAs with an HRA. However, these figures were included in the total. The time series data also shows the figures reported by the individual LA, despite not having an HRA.
A7: 4 | B7: 202103 | C7: Dorset (UA) | D7: This local authority submitted HRA figures but does not have an HRA. The published suplementary COR table included individual LA data only for LAs with an HRA. However, these figures were included in the total. The time series data also shows the figures reported by the individual LA, despite not having an HRA.
A8: 5 | B8: 202103 | C8: Eden | D8: This local authority submitted HRA figures but does not have an HRA. The published suplementary COR table included individual LA data only for LAs with an HRA. However, these figures were included in the total. The time series data also shows the figures reported by the individual LA, despite not having an HRA.
A9: 6 | B9: 202103 | C9: Amber Valley | D9: This local authority submitted HRA figures but does not have an HRA. The published suplementary COR table included individual LA data only for LAs with an HRA. However, these figures were included in the total. The time series data also shows the figures reported by the individual LA, despite not having an HRA.
A10: 7 | B10: 202103 | C10: Kings Lynn & West Norfolk | D10: This local authority submitted HRA figures but does not have an HRA. The published suplementary COR table included individual LA data only for LAs with an HRA. However, these figures were included in the total. The time series data also shows the figures reported by the individual LA, despite not having an HRA.
A11: 8 | B11: 202303 | C11: Liverpool | D11: This local authority submitted HRA figures but does not have an HRA. The published suplementary COR table included individual LA data only for LAs with an HRA. However, these figures were included in the total. The time series data also shows the figures reported by the individual LA, despite not having an HRA.

Sheet Local_authorities
A1: Local authorities that have been included in the time series publication
A2: This worksheet contains one table.
A3: Some cells refer to notes which can be found in the 'Notes' worksheet. Blank cells in the 'End' column (column H) mean the local authority is still currently active. Blank cells in the 'Notes' column (column I) mean there are no notes for that local authority.
A4: LA_LGF_Code [note 3] | B4: ONS_Code | C4: LA_Name | D4: Class | E4: Subclass | F4: Region | G4: Start [note 1] | H4: End [note 1] | I4: Notes [note 3]
A5: E3831 | B5: E07000223 | C5: Adur | D5: Shire District | E5: Shire District | F5: South East | G5: 201903
A6: E0931 | B6: E07000026 | C6: Allerdale | D6: Shire District | E6: Shire District | F6: North West | G6: 201903 | H6: 202303 | I6: Merged into Cumberland Council in April 2023.
A7: E1031 | B7: E07000032 | C7: Amber Valley | D7: Shire District | E7: Shire District | F7: East Midlands | G7: 201903
A8: E3832 | B8: E07000224 | C8: Arun | D8: Shire District | E8: Shire District | F8: South East | G8: 201903
A9: E3031 | B9: E07000170 | C9: Ashfield | D9: Shire District | E9: Shire District | F9: East Midlands | G9: 201903
A10: E2231 | B10: E07000105 | C10: Ashford | D10: Shire District | E10: Shire District | F10: South East | G10: 201903
A11: E7050 | B11: E23000036 | C11: Avon & Somerset Police and Crime Commissioner and Chief Constable | D11: Other | E11: Police Authority | F11: South West | G11: 201903
A12: E6101 | B12: E31000001 | C12: Avon Combined Fire and Rescue Authority | D12: Other | E12: Fire and Rescue Authority | F12: South West | G12: 201903
A13: E0431 | B13: E07000004 | C13: Aylesbury Vale | D13: Shire District | E13: Shire District | F13: South East | G13: 201903 | H13: 202003 | I13: Merged into Buckinghamshire in April 2020.
A14: E3531 | B14: E07000200 | C14: Babergh | D14: Shire District | E14: Shire District | F14: East of England | G14: 201903
A15: E5030 | B15: E09000002 | C15: Barking & Dagenham | D15: London Borough | E15: London Borough | F15: London | G15: 201903
A16: E5031 | B16: E09000003 | C16: Barnet | D16: London Borough | E16: London Borough | F16: London | G16: 201903
A17: E4401 | B17: E08000016 | C17: Barnsley | D17: Metropolitan District | E17: Metropolitan District | F17: Yorkshire and The Humber | G17: 201903
A18: E0932 | B18: E07000027 | C18: Barrow-in-Furness | D18: Shire District | E18: Shire District | F18: North West | G18: 201903 | H18: 202303 | I18: Merged into Westmorland and Furness in April 2023.
A19: E1531 | B19: E07000066 | C19: Basildon | D19: Shire District | E19: Shire District | F19: East of England | G19: 201903
A20: E1731 | B20: E07000084 | C20: Basingstoke & Deane | D20: Shire District | E20: Shire District | F20: South East | G20: 201903
A21: E3032 | B21: E07000171 | C21: Bassetlaw | D21: Shire District | E21: Shire District | F21: East Midlands | G21: 201903
A22: E0101 | B22: E06000022 | C22: Bath & North East Somerset | D22: Unitary Authority | E22: Unitary Authority | F22: South West | G22: 201903
A23: E0202 | B23: E06000055 | C23: Bedford | D23: Unitary Authority | E23: Unitary Authority | F23: East of England | G23: 201903
A24: E6102 | B24: E31000002 | C24: Bedfordshire Combined Fire Authority | D24: Other | E24: Fire and Rescue Authority | F24: East of England | G24: 201903
A25: E7002 | B25: E23000026 | C25: Bedfordshire Police and Crime Commissioner and Chief Constable | D25: Other | E25: Police Authority | F25: East of England | G25: 201903
A26: E6103 | B26: E31000003 | C26: Berkshire Combined Fire Authority | D26: Other | E26: Fire and Rescue Authority | F26: South East | G26: 201903
A27: E5032 | B27: E09000004 | C27: Bexley | D27: London Borough | E27: London Borough | F27: London | G27: 201903
A28: E4601 | B28: E08000025 | C28: Birmingham | D28: Metropolitan District | E28: Metropolitan District | F28: West Midlands | G28: 201903
A29: E2431 | B29: E07000129 | C29: Blaby | D29: Shire District | E29: Shire District | F29: East Midlands | G29: 201903
A30: E2301 | B30: E06000008 | C30: Blackburn with Darwen | D30: Unitary Authority | E30: Unitary Authority | F30: North West | G30: 201903
... A34: E2531 | B34: E07000136 | C34: Boston | D34: Shire District | E34: Shire District | F34: East Midlands | G34: 201903
A35: E1202 | B35: E06000028 | C35: Bournemouth | D35: Unitary Authority | E35: Unitary Authority | F35: South West | G35: 201903 | H35: 201903 | I35: Merged into Bournemouth, Christchurch and Poole in April 2019.
A36: E1204 | B36: E06000058 | C36: Bournemouth, Christchurch & Poole | D36: Unitary Authority | E36: Unitary Authority | F36: South West | G36: 202003 | I36: Formed by a merger of Bournemouth, Christchurch and Poole in April 2019.
A37: E0301 | B37: E06000036 | C37: Bracknell Forest | D37: Unitary Authority | E37: Unitary Authority | F37: South East | G37: 201903
A38: E4701 | B38: E08000032 | C38: Bradford | D38: Metropolitan District | E38: Metropolitan District | F38: Yorkshire and The Humber | G38: 201903
A39: E1532 | B39: E07000067 | C39: Braintree | D39: Shire District | E39: Shire District | F39: East of England | G39: 201903
A40: E2631 | B40: E07000143 | C40: Breckland | D40: Shire District | E40: Shire District | F40: East of England | G40: 201903
A41: E5033 | B41: E09000005 | C41: Brent | D41: London Borough | E41: London Borough | F41: London | G41: 201903
A42: E1533 | B42: E07000068 | C42: Brentwood | D42: Shire District | E42: Shire District | F42: East of England | G42: 201903
A43: E1401 | B43: E06000043 | C43: Brighton & Hove | D43: Unitary Authority | E43: Unitary Authority | F43: South East | G43: 201903
...

Sheet Totals
A1: Aggregate totals included in data set
A2: This worksheet contains one table.
A3: Some cells refer to notes which can be found in the 'Notes' worksheet. Blank cells in the 'Notes' column (column F) mean there are no notes for that total.
A4: LA_LGF_Code [note 4] | B4: ONS_Code | C4: Name | D4: Class | E4: Subclass | F4: Notes
A5: ENG_1 | B5: E92000001 | C5: England (grossed) | D5: Eng | E5: Eng | F5: In years where a complete data set was received from all local authorities, England and class totals are summed from Local Authority data. In years where the data set is not complete, England (but not class totals, which remain a simple sum) are estimated using a grossing method which is described in the Technical Notes which are published with the Capital Outturn Return Statistics Release on gov.uk.
A6: ENG_2 | B6: E92000001 | C6: England (grossed, excluding double counting) | D6: Eng | E6: Eng | F6: Transfers between Local Authorities and the GLA are counted for both sides, resulting in double counting. The England (grossed, excluding double counting) value deducts these variables from the England (grossed) total. Categories on this row will often not sum up, as transfers between local authorities are reported only at a total category level (e.g. we know transfers from other local authorities at a 'Total Receipts' level - [...]rectot variables - , but not from which type of receipts - [...]rectng, [...]recint, [...]recrpy, or [...]recinv)
A7: LB | B7: E09 | C7: London Boroughs | D7: London Borough | E7: London Borough | F7: The Greater London Authority is not included in this category. It is included within the 'Other' class and treated as belonging to its own distinct subclass.
A8: MD | B8: E08 | C8: Metropolitan Districts | D8: Met District | E8: Met District
A9: UA | B9: E06 | C9: Unitary Authorities | D9: Unitary Authority | E9: Unitary Authority
A10: SC | B10: E10 | C10: Shire Counties | D10: Shire County | E10: Shire County
A11: SD | B11: E07 | C11: Shire Districts | D11: Shire District | E11: Shire District
A12: O | B12: EOTH | C12: Other Authorities | D12: Other | E12: Other | F12: There are no local authorities with a subclass of 'Other', this is used for the total of the 6 Other subcategories.
A13: P | B13: P | C13: Police Authorities | D13: Other | E13: Police
A14: FRS | B14: FR | C14: Fire & Rescue Authorities | D14: Other | E14: Fire
A15: NPA | B15: NPA | C15: National Park Authorities | D15: Other | E15: Park
A16: WA | B16: WA | C16: Waste Authorities | D16: Other | E16: Waste
A17: GLA | B17: GLA | C17: Greater London Authority | D17: Other | E17: GLA
A18: CA | B18: CA | C18: Combined Authorities | D18: Other | E18: Combined Authority
